export class AppError extends Error {
  constructor(
    message: string,
    public code: string,
    public statusCode: number = 500
  ) {
    super(message);
    this.name = 'AppError';
  }
}

export class AuthenticationError extends AppError {
  constructor(message: string = 'Authentication failed') {
    super(message, 'AUTH_ERROR', 401);
    this.name = 'AuthenticationError';
  }
}

export class AuthorizationError extends AppError {
  constructor(message: string = 'Not authorized') {
    super(message, 'AUTHORIZATION_ERROR', 403);
    this.name = 'AuthorizationError';
  }
}

export class ValidationError extends AppError {
  constructor(message: string = 'Validation failed') {
    super(message, 'VALIDATION_ERROR', 400);
    this.name = 'ValidationError';
  }
}

export class NotFoundError extends AppError {
  constructor(message: string = 'Resource not found') {
    super(message, 'NOT_FOUND', 404);
    this.name = 'NotFoundError';
  }
}

export class NetworkError extends AppError {
  constructor(message: string = 'Network error') {
    super(message, 'NETWORK_ERROR', 503);
    this.name = 'NetworkError';
  }
}

export const handleError = (error: unknown): string => {
  console.error('[Error]', error);

  if (error instanceof AppError) {
    return error.message;
  }

  if (error instanceof Error) {
    if (error.message.includes('network')) {
      return 'Network error. Please check your connection.';
    }
    if (error.message.includes('timeout')) {
      return 'Request timed out. Please try again.';
    }
    return error.message;
  }

  return 'An unexpected error occurred. Please try again.';
};

export const logError = (
  error: unknown,
  context?: Record<string, any>
): void => {
  const errorInfo = {
    timestamp: new Date().toISOString(),
    error:
      error instanceof Error
        ? {
            name: error.name,
            message: error.message,
            stack: error.stack,
          }
        : error,
    context,
  };

  console.error('[Error Log]', JSON.stringify(errorInfo, null, 2));
};

export const withErrorHandling = async <T>(
  fn: () => Promise<T>,
  errorMessage?: string
): Promise<T | null> => {
  try {
    return await fn();
  } catch (error) {
    logError(error, { customMessage: errorMessage });
    return null;
  }
};
